Workbook

Sheet Test Account 1
A1: Transaction Date | B1: Posted Date | C1: Card No. | D1: Description | E1: Category | F1: Debit | G1: Credit | H1: OMIT | I1: DateOverride | J1: Date | K1: CalcDate | L1: Amounts Combined
A2: 45292 | B2: 45292 | C2: 2188 | D2: Apples 1 | E2: Gas/Automotive | F2: 111 | I2: FALSE | K2: =IF(I2=FALSE, IF(A2<B2,A2,B2), J2) -> 45292 | L2: =IF(H2=FALSE,F2-G2,0) -> 111
A3: 45293 | B3: 45293 | C3: 2188 | D3: Oranges 2 | E3: Merchandise | F3: 222 | I3: FALSE | K3: =IF(I3=FALSE, IF(A3<B3,A3,B3), J3) -> 45293 | L3: =IF(H3=FALSE,F3-G3,0) -> 222
A4: 45294 | B4: 45294 | C4: 2188 | D4: Grapes 3 | E4: Phone/Cable | F4: 333 | I4: FALSE | K4: =IF(I4=FALSE, IF(A4<B4,A4,B4), J4) -> 45294 | L4: =IF(H4=FALSE,F4-G4,0) -> 333
A5: 45295 | B5: 45295 | C5: 2188 | D5: Berry 4 | E5: Merchandise | F5: 444 | I5: FALSE | K5: =IF(I5=FALSE, IF(A5<B5,A5,B5), J5) -> 45295 | L5: =IF(H5=FALSE,F5-G5,0) -> 444
A6: 45296 | B6: 45296 | C6: 2188 | D6: Watermelon 5 | E6: Entertainment | F6: 555 | I6: FALSE | K6: =IF(I6=FALSE, IF(A6<B6,A6,B6), J6) -> 45296 | L6: =IF(H6=FALSE,F6-G6,0) -> 555
A7: 45297 | B7: 45297 | C7: 2188 | D7: Expense 6 | E7: Dining | F7: 100 | I7: FALSE | K7: =IF(I7=FALSE, IF(A7<B7,A7,B7), J7) -> 45297 | L7: =IF(H7=FALSE,F7-G7,0) -> 100
A8: 45298 | B8: 45298 | C8: 2188 | D8: Expense 7 | E8: Merchandise | F8: 100 | I8: FALSE | K8: =IF(I8=FALSE, IF(A8<B8,A8,B8), J8) -> 45298 | L8: =IF(H8=FALSE,F8-G8,0) -> 100
A9: 45299 | B9: 45299 | C9: 2188 | D9: Expense 8 | E9: Dining | F9: 100 | I9: FALSE | K9: =IF(I9=FALSE, IF(A9<B9,A9,B9), J9) -> 45299 | L9: =IF(H9=FALSE,F9-G9,0) -> 100
A10: 45300 | B10: 45300 | C10: 2188 | D10: Expense 9 | E10: Professional Services | F10: 100 | I10: FALSE | K10: =IF(I10=FALSE, IF(A10<B10,A10,B10), J10) -> 45300 | L10: =IF(H10=FALSE,F10-G10,0) -> 100
A11: 45301 | B11: 45301 | C11: 2188 | D11: Expense 10 | E11: Lodging | F11: 100 | I11: FALSE | K11: =IF(I11=FALSE, IF(A11<B11,A11,B11), J11) -> 45301 | L11: =IF(H11=FALSE,F11-G11,0) -> 100
A12: 45302 | B12: 45302 | C12: 2188 | D12: Expense 11 | E12: Gas/Automotive | F12: 100 | I12: FALSE | K12: =IF(I12=FALSE, IF(A12<B12,A12,B12), J12) -> 45302 | L12: =IF(H12=FALSE,F12-G12,0) -> 100
A13: 45303 | B13: 45303 | C13: 2188 | D13: Expense 12 | E13: Dining | F13: 100 | I13: FALSE | K13: =IF(I13=FALSE, IF(A13<B13,A13,B13), J13) -> 45303 | L13: =IF(H13=FALSE,F13-G13,0) -> 100
A14: 45304 | B14: 45304 | C14: 2188 | D14: Expense 13 | E14: Payment/Credit | G14: 100 | I14: FALSE | K14: =IF(I14=FALSE, IF(A14<B14,A14,B14), J14) -> 45304 | L14: =IF(H14=FALSE,F14-G14,0) -> -100
A15: 45305 | B15: 45305 | C15: 2188 | D15: Expense 14 | E15: Merchandise | F15: 100 | I15: FALSE | K15: =IF(I15=FALSE, IF(A15<B15,A15,B15), J15) -> 45305 | L15: =IF(H15=FALSE,F15-G15,0) -> 100
A16: 45306 | B16: 45306 | C16: 2188 | D16: Expense 15 | E16: Merchandise | F16: 100 | I16: FALSE | K16: =IF(I16=FALSE, IF(A16<B16,A16,B16), J16) -> 45306 | L16: =IF(H16=FALSE,F16-G16,0) -> 100
A17: 45307 | B17: 45307 | C17: 2188 | D17: Expense 16 | E17: Dining | F17: 100 | I17: FALSE | K17: =IF(I17=FALSE, IF(A17<B17,A17,B17), J17) -> 45307 | L17: =IF(H17=FALSE,F17-G17,0) -> 100
A18: 45308 | B18: 45308 | C18: 2188 | D18: Expense 17 | E18: Dining | F18: 100 | H18: TRUE | I18: FALSE | K18: =IF(I18=FALSE, IF(A18<B18,A18,B18), J18) -> 45308 | L18: =IF(H18=FALSE,F18-G18,0) -> 0
A19: 45309 | B19: 45309 | C19: 2188 | D19: Expense 18 | E19: Dining | F19: 100 | I19: FALSE | K19: =IF(I19=FALSE, IF(A19<B19,A19,B19), J19) -> 45309 | L19: =IF(H19=FALSE,F19-G19,0) -> 100
A20: 45310 | B20: 45310 | C20: 2188 | D20: Expense 19 | E20: Dining | F20: 100 | I20: FALSE | K20: =IF(I20=FALSE, IF(A20<B20,A20,B20), J20) -> 45310 | L20: =IF(H20=FALSE,F20-G20,0) -> 100
A21: 45311 | B21: 45311 | C21: 2188 | D21: Expense 20 | E21: Dining | F21: 100 | I21: FALSE | K21: =IF(I21=FALSE, IF(A21<B21,A21,B21), J21) -> 45311 | L21: =IF(H21=FALSE,F21-G21,0) -> 100
A22: 45312 | B22: 45312 | C22: 2188 | D22: Expense 21 | E22: Dining | F22: 100 | I22: FALSE | K22: =IF(I22=FALSE, IF(A22<B22,A22,B22), J22) -> 45312 | L22: =IF(H22=FALSE,F22-G22,0) -> 100
A23: 45313 | B23: 45313 | C23: 2188 | D23: Expense 22 | E23: Dining | F23: 100 | I23: FALSE | K23: =IF(I23=FALSE, IF(A23<B23,A23,B23), J23) -> 45313 | L23: =IF(H23=FALSE,F23-G23,0) -> 100
A24: 45314 | B24: 45314 | C24: 2188 | D24: Expense 23 | E24: Dining | F24: 100 | I24: FALSE | K24: =IF(I24=FALSE, IF(A24<B24,A24,B24), J24) -> 45314 | L24: =IF(H24=FALSE,F24-G24,0) -> 100
A25: 45315 | B25: 45315 | C25: 2188 | D25: Expense 24 | E25: Dining | F25: 100 | I25: FALSE | K25: =IF(I25=FALSE, IF(A25<B25,A25,B25), J25) -> 45315 | L25: =IF(H25=FALSE,F25-G25,0) -> 100
A26: 45316 | B26: 45316 | C26: 2188 | D26: Expense 25 | E26: Dining | F26: 100 | I26: FALSE | K26: =IF(I26=FALSE, IF(A26<B26,A26,B26), J26) -> 45316 | L26: =IF(H26=FALSE,F26-G26,0) -> 100
A27: 45317 | B27: 45317 | C27: 2188 | D27: Expense 26 | E27: Dining | F27: 100 | I27: FALSE | K27: =IF(I27=FALSE, IF(A27<B27,A27,B27), J27) -> 45317 | L27: =IF(H27=FALSE,F27-G27,0) -> 100
A28: 45318 | B28: 45318 | C28: 2188 | D28: Expense 27 | E28: Other Travel | F28: 100 | I28: FALSE | K28: =IF(I28=FALSE, IF(A28<B28,A28,B28), J28) -> 45318 | L28: =IF(H28=FALSE,F28-G28,0) -> 100
A29: 45319 | B29: 45319 | C29: 2188 | D29: Expense 28 | E29: Dining | F29: 100 | I29: FALSE | K29: =IF(I29=FALSE, IF(A29<B29,A29,B29), J29) -> 45319 | L29: =IF(H29=FALSE,F29-G29,0) -> 100
A30: 45320 | B30: 45320 | C30: 2188 | D30: Expense 29 | E30: Merchandise | F30: 100 | I30: FALSE | K30: =IF(I30=FALSE, IF(A30<B30,A30,B30), J30) -> 45320 | L30: =IF(H30=FALSE,F30-G30,0) -> 100
... A34: 45322 | B34: 45324 | C34: 2188 | D34: Oranges 2 | E34: Merchandise | F34: 222 | I34: FALSE | K34: =IF(I34=FALSE, IF(A34<B34,A34,B34), J34) -> 45322 | L34: =IF(H34=FALSE,F34-G34,0) -> 222
A35: 45323 | B35: 45325 | C35: 2188 | D35: Grapes 3 | E35: Phone/Cable | F35: -333 | I35: TRUE | J35: 45322 | K35: =IF(I35=FALSE, IF(A35<B35,A35,B35), J35) -> 45322 | L35: =IF(H35=FALSE,F35-G35,0) -> -333
A36: 45324 | B36: 45326 | C36: 2188 | D36: Berry 4 | E36: Merchandise | F36: -444 | I36: TRUE | J36: 45322 | K36: =IF(I36=FALSE, IF(A36<B36,A36,B36), J36) -> 45322 | L36: =IF(H36=FALSE,F36-G36,0) -> -444
A37: 45325 | B37: 45327 | C37: 2188 | D37: Watermelon 5 | E37: Entertainment | F37: -555 | I37: TRUE | J37: 45322 | K37: =IF(I37=FALSE, IF(A37<B37,A37,B37), J37) -> 45322 | L37: =IF(H37=FALSE,F37-G37,0) -> -555
A38: 45326 | B38: 45328 | C38: 2188 | D38: Expense 6 | E38: Dining | F38: 100 | I38: FALSE | K38: =IF(I38=FALSE, IF(A38<B38,A38,B38), J38) -> 45326 | L38: =IF(H38=FALSE,F38-G38,0) -> 100
A39: 45327 | B39: 45329 | C39: 2188 | D39: Expense 7 | E39: Merchandise | F39: 100 | I39: FALSE | K39: =IF(I39=FALSE, IF(A39<B39,A39,B39), J39) -> 45327 | L39: =IF(H39=FALSE,F39-G39,0) -> 100
A40: 45328 | B40: 45330 | C40: 2188 | D40: Expense 8 | E40: Dining | F40: 100 | I40: FALSE | K40: =IF(I40=FALSE, IF(A40<B40,A40,B40), J40) -> 45328 | L40: =IF(H40=FALSE,F40-G40,0) -> 100
A41: 45329 | B41: 45331 | C41: 2188 | D41: Expense 9 | E41: Professional Services | F41: 100 | I41: FALSE | K41: =IF(I41=FALSE, IF(A41<B41,A41,B41), J41) -> 45329 | L41: =IF(H41=FALSE,F41-G41,0) -> 100
A42: 45330 | B42: 45332 | C42: 2188 | D42: Expense 10 | E42: Lodging | F42: 100 | I42: FALSE | K42: =IF(I42=FALSE, IF(A42<B42,A42,B42), J42) -> 45330 | L42: =IF(H42=FALSE,F42-G42,0) -> 100
A43: 45331 | B43: 45333 | C43: 2188 | D43: Expense 11 | E43: Gas/Automotive | F43: 100 | I43: FALSE | K43: =IF(I43=FALSE, IF(A43<B43,A43,B43), J43) -> 45331 | L43: =IF(H43=FALSE,F43-G43,0) -> 100
...

Sheet Test Account 2
A1: Transaction Date | B1: Posted Date | C1: Card No. | D1: Description | E1: Category | F1: Debit | G1: Credit | H1: OMIT | I1: DateOverride | J1: Date | K1: CalcDate | L1: Amounts Combined
A2: 45292 | B2: 45292 | C2: 2188 | D2: Apples 1 | E2: Gas/Automotive | F2: 111 | I2: FALSE | K2: =IF(I2=FALSE, IF(A2<B2,A2,B2), J2) -> 45292 | L2: =IF(H2=FALSE,F2-G2,0) -> 111 | N2: =COUNTA(A2:A125) -> 124
A3: 45293 | B3: 45293 | C3: 2188 | D3: Oranges 2 | E3: Merchandise | F3: 222 | I3: FALSE | K3: =IF(I3=FALSE, IF(A3<B3,A3,B3), J3) -> 45293 | L3: =IF(H3=FALSE,F3-G3,0) -> 222
A4: 45294 | B4: 45294 | C4: 2188 | D4: Grapes 3 | E4: Phone/Cable | F4: 333 | I4: FALSE | K4: =IF(I4=FALSE, IF(A4<B4,A4,B4), J4) -> 45294 | L4: =IF(H4=FALSE,F4-G4,0) -> 333
A5: 45295 | B5: 45295 | C5: 2188 | D5: Berry 4 | E5: Merchandise | F5: 444 | I5: FALSE | K5: =IF(I5=FALSE, IF(A5<B5,A5,B5), J5) -> 45295 | L5: =IF(H5=FALSE,F5-G5,0) -> 444
A6: 45296 | B6: 45296 | C6: 2188 | D6: Watermelon 5 | E6: Entertainment | F6: 555 | I6: FALSE | K6: =IF(I6=FALSE, IF(A6<B6,A6,B6), J6) -> 45296 | L6: =IF(H6=FALSE,F6-G6,0) -> 555
A7: 45297 | B7: 45297 | C7: 2188 | D7: Expense 6 | E7: Dining | F7: 100 | I7: FALSE | K7: =IF(I7=FALSE, IF(A7<B7,A7,B7), J7) -> 45297 | L7: =IF(H7=FALSE,F7-G7,0) -> 100
A8: 45298 | B8: 45298 | C8: 2188 | D8: Expense 7 | E8: Merchandise | F8: 100 | I8: FALSE | K8: =IF(I8=FALSE, IF(A8<B8,A8,B8), J8) -> 45298 | L8: =IF(H8=FALSE,F8-G8,0) -> 100
A9: 45299 | B9: 45299 | C9: 2188 | D9: Expense 8 | E9: Dining | F9: 100 | I9: FALSE | K9: =IF(I9=FALSE, IF(A9<B9,A9,B9), J9) -> 45299 | L9: =IF(H9=FALSE,F9-G9,0) -> 100
A10: 45300 | B10: 45300 | C10: 2188 | D10: Expense 9 | E10: Professional Services | F10: 100 | I10: FALSE | K10: =IF(I10=FALSE, IF(A10<B10,A10,B10), J10) -> 45300 | L10: =IF(H10=FALSE,F10-G10,0) -> 100
A11: 45301 | B11: 45301 | C11: 2188 | D11: Expense 10 | E11: Lodging | F11: 100 | I11: FALSE | K11: =IF(I11=FALSE, IF(A11<B11,A11,B11), J11) -> 45301 | L11: =IF(H11=FALSE,F11-G11,0) -> 100
A12: 45302 | B12: 45302 | C12: 2188 | D12: Expense 11 | E12: Gas/Automotive | F12: 100 | I12: FALSE | K12: =IF(I12=FALSE, IF(A12<B12,A12,B12), J12) -> 45302 | L12: =IF(H12=FALSE,F12-G12,0) -> 100
A13: 45303 | B13: 45303 | C13: 2188 | D13: Expense 12 | E13: Dining | F13: 100 | I13: FALSE | K13: =IF(I13=FALSE, IF(A13<B13,A13,B13), J13) -> 45303 | L13: =IF(H13=FALSE,F13-G13,0) -> 100
A14: 45304 | B14: 45304 | C14: 2188 | D14: Expense 13 | E14: Payment/Credit | G14: 100 | I14: FALSE | K14: =IF(I14=FALSE, IF(A14<B14,A14,B14), J14) -> 45304 | L14: =IF(H14=FALSE,F14-G14,0) -> -100
A15: 45305 | B15: 45305 | C15: 2188 | D15: Expense 14 | E15: Merchandise | F15: 100 | I15: FALSE | K15: =IF(I15=FALSE, IF(A15<B15,A15,B15), J15) -> 45305 | L15: =IF(H15=FALSE,F15-G15,0) -> 100
A16: 45306 | B16: 45306 | C16: 2188 | D16: Expense 15 | E16: Merchandise | F16: 100 | I16: FALSE | K16: =IF(I16=FALSE, IF(A16<B16,A16,B16), J16) -> 45306 | L16: =IF(H16=FALSE,F16-G16,0) -> 100
A17: 45307 | B17: 45307 | C17: 2188 | D17: Expense 16 | E17: Dining | F17: 100 | I17: FALSE | K17: =IF(I17=FALSE, IF(A17<B17,A17,B17), J17) -> 45307 | L17: =IF(H17=FALSE,F17-G17,0) -> 100
A18: 45308 | B18: 45308 | C18: 2188 | D18: Expense 17 | E18: Dining | F18: 100 | H18: TRUE | I18: FALSE | K18: =IF(I18=FALSE, IF(A18<B18,A18,B18), J18) -> 45308 | L18: =IF(H18=FALSE,F18-G18,0) -> 0
A19: 45309 | B19: 45309 | C19: 2188 | D19: Expense 18 | E19: Dining | F19: 100 | I19: FALSE | K19: =IF(I19=FALSE, IF(A19<B19,A19,B19), J19) -> 45309 | L19: =IF(H19=FALSE,F19-G19,0) -> 100
A20: 45310 | B20: 45310 | C20: 2188 | D20: Expense 19 | E20: Dining | F20: 100 | I20: FALSE | K20: =IF(I20=FALSE, IF(A20<B20,A20,B20), J20) -> 45310 | L20: =IF(H20=FALSE,F20-G20,0) -> 100
A21: 45311 | B21: 45311 | C21: 2188 | D21: Expense 20 | E21: Dining | F21: 100 | I21: FALSE | K21: =IF(I21=FALSE, IF(A21<B21,A21,B21), J21) -> 45311 | L21: =IF(H21=FALSE,F21-G21,0) -> 100
A22: 45312 | B22: 45312 | C22: 2188 | D22: Expense 21 | E22: Dining | F22: 100 | I22: FALSE | K22: =IF(I22=FALSE, IF(A22<B22,A22,B22), J22) -> 45312 | L22: =IF(H22=FALSE,F22-G22,0) -> 100
A23: 45313 | B23: 45313 | C23: 2188 | D23: Expense 22 | E23: Dining | F23: 100 | I23: FALSE | K23: =IF(I23=FALSE, IF(A23<B23,A23,B23), J23) -> 45313 | L23: =IF(H23=FALSE,F23-G23,0) -> 100
A24: 45314 | B24: 45314 | C24: 2188 | D24: Expense 23 | E24: Dining | F24: 100 | I24: FALSE | K24: =IF(I24=FALSE, IF(A24<B24,A24,B24), J24) -> 45314 | L24: =IF(H24=FALSE,F24-G24,0) -> 100
A25: 45315 | B25: 45315 | C25: 2188 | D25: Expense 24 | E25: Dining | F25: 100 | I25: FALSE | K25: =IF(I25=FALSE, IF(A25<B25,A25,B25), J25) -> 45315 | L25: =IF(H25=FALSE,F25-G25,0) -> 100
A26: 45316 | B26: 45316 | C26: 2188 | D26: Expense 25 | E26: Dining | F26: 100 | I26: FALSE | K26: =IF(I26=FALSE, IF(A26<B26,A26,B26), J26) -> 45316 | L26: =IF(H26=FALSE,F26-G26,0) -> 100
A27: 45317 | B27: 45317 | C27: 2188 | D27: Expense 26 | E27: Dining | F27: 100 | I27: FALSE | K27: =IF(I27=FALSE, IF(A27<B27,A27,B27), J27) -> 45317 | L27: =IF(H27=FALSE,F27-G27,0) -> 100
A28: 45318 | B28: 45318 | C28: 2188 | D28: Expense 27 | E28: Other Travel | F28: 100 | I28: FALSE | K28: =IF(I28=FALSE, IF(A28<B28,A28,B28), J28) -> 45318 | L28: =IF(H28=FALSE,F28-G28,0) -> 100
A29: 45319 | B29: 45319 | C29: 2188 | D29: Expense 28 | E29: Dining | F29: 100 | I29: FALSE | K29: =IF(I29=FALSE, IF(A29<B29,A29,B29), J29) -> 45319 | L29: =IF(H29=FALSE,F29-G29,0) -> 100
A30: 45320 | B30: 45320 | C30: 2188 | D30: Expense 29 | E30: Merchandise | F30: 100 | I30: FALSE | K30: =IF(I30=FALSE, IF(A30<B30,A30,B30), J30) -> 45320 | L30: =IF(H30=FALSE,F30-G30,0) -> 100
... A44: 45332 | B44: 45334 | C44: 2188 | D44: Expense 12 | E44: Dining | F44: 100 | I44: FALSE | K44: =IF(I44=FALSE, IF(A44<B44,A44,B44), J44) -> 45332 | L44: =IF(H44=FALSE,F44-G44,0) -> 100
A45: 45333 | B45: 45335 | C45: 2188 | D45: Expense 13 | E45: Payment/Credit | G45: 100 | I45: FALSE | K45: =IF(I45=FALSE, IF(A45<B45,A45,B45), J45) -> 45333 | L45: =IF(H45=FALSE,F45-G45,0) -> -100
A46: 45334 | B46: 45336 | C46: 2188 | D46: Expense 14 | E46: Merchandise | F46: 100 | I46: FALSE | K46: =IF(I46=FALSE, IF(A46<B46,A46,B46), J46) -> 45334 | L46: =IF(H46=FALSE,F46-G46,0) -> 100
A47: 45335 | B47: 45337 | C47: 2188 | D47: Expense 15 | E47: Merchandise | F47: 100 | I47: FALSE | K47: =IF(I47=FALSE, IF(A47<B47,A47,B47), J47) -> 45335 | L47: =IF(H47=FALSE,F47-G47,0) -> 100
A48: 45336 | B48: 45338 | C48: 2188 | D48: Expense 16 | E48: Dining | F48: 100 | I48: FALSE | K48: =IF(I48=FALSE, IF(A48<B48,A48,B48), J48) -> 45336 | L48: =IF(H48=FALSE,F48-G48,0) -> 100
A49: 45337 | B49: 45339 | C49: 2188 | D49: Expense 17 | E49: Dining | F49: 100 | H49: TRUE | I49: FALSE | K49: =IF(I49=FALSE, IF(A49<B49,A49,B49), J49) -> 45337 | L49: =IF(H49=FALSE,F49-G49,0) -> 0
A50: 45338 | B50: 45340 | C50: 2188 | D50: Expense 18 | E50: Dining | F50: 100 | I50: FALSE | K50: =IF(I50=FALSE, IF(A50<B50,A50,B50), J50) -> 45338 | L50: =IF(H50=FALSE,F50-G50,0) -> 100
A51: 45339 | B51: 45341 | C51: 2188 | D51: Expense 19 | E51: Dining | F51: 100 | I51: FALSE | K51: =IF(I51=FALSE, IF(A51<B51,A51,B51), J51) -> 45339 | L51: =IF(H51=FALSE,F51-G51,0) -> 100
A52: 45340 | B52: 45342 | C52: 2188 | D52: Expense 20 | E52: Dining | F52: 100 | I52: FALSE | K52: =IF(I52=FALSE, IF(A52<B52,A52,B52), J52) -> 45340 | L52: =IF(H52=FALSE,F52-G52,0) -> 100
A53: 45341 | B53: 45343 | C53: 2188 | D53: Expense 21 | E53: Dining | F53: 100 | I53: FALSE | K53: =IF(I53=FALSE, IF(A53<B53,A53,B53), J53) -> 45341 | L53: =IF(H53=FALSE,F53-G53,0) -> 100
...

Sheet Test Account 3
A1: Posted Date | B1: Card No. | C1: Description | D1: Category | E1: Debit | F1: Credit | G1: OMIT | H1: DateOverride | I1: Date | J1: CalcDate | K1: Amounts Combined
A2: 45292 | B2: 2188 | C2: Apples 1 | D2: Gas/Automotive | E2: 111 | H2: FALSE | J2: =IF(H2=FALSE, A2, I2) -> 45292 | K2: =IF(G2=FALSE, E2-F2, 0) -> 111 | N2: =COUNTA(A2:A125) -> 124
A3: 45293 | B3: 2188 | C3: Oranges 2 | D3: Merchandise | E3: -222 | H3: FALSE | J3: =IF(H3=FALSE, A3, I3) -> 45293 | K3: =IF(G3=FALSE, E3-F3, 0) -> -222
A4: 45294 | B4: 2188 | C4: Grapes 3 | D4: Phone/Cable | E4: 333 | H4: FALSE | J4: =IF(H4=FALSE, A4, I4) -> 45294 | K4: =IF(G4=FALSE, E4-F4, 0) -> 333
A5: 45295 | B5: 2188 | C5: Berry 4 | D5: Merchandise | E5: -444 | H5: FALSE | J5: =IF(H5=FALSE, A5, I5) -> 45295 | K5: =IF(G5=FALSE, E5-F5, 0) -> -444
A6: 45296 | B6: 2188 | C6: Watermelon 5 | D6: Entertainment | E6: 555 | H6: FALSE | J6: =IF(H6=FALSE, A6, I6) -> 45296 | K6: =IF(G6=FALSE, E6-F6, 0) -> 555
A7: 45297 | B7: 2188 | C7: Expense 6 | D7: Dining | E7: -100 | H7: FALSE | J7: =IF(H7=FALSE, A7, I7) -> 45297 | K7: =IF(G7=FALSE, E7-F7, 0) -> -100
A8: 45298 | B8: 2188 | C8: Expense 7 | D8: Merchandise | E8: 100 | H8: FALSE | J8: =IF(H8=FALSE, A8, I8) -> 45298 | K8: =IF(G8=FALSE, E8-F8, 0) -> 100
A9: 45299 | B9: 2188 | C9: Expense 8 | D9: Dining | E9: -100 | H9: FALSE | J9: =IF(H9=FALSE, A9, I9) -> 45299 | K9: =IF(G9=FALSE, E9-F9, 0) -> -100
A10: 45300 | B10: 2188 | C10: Expense 9 | D10: Professional Services | E10: 100 | H10: FALSE | J10: =IF(H10=FALSE, A10, I10) -> 45300 | K10: =IF(G10=FALSE, E10-F10, 0) -> 100
A11: 45301 | B11: 2188 | C11: Expense 10 | D11: Lodging | E11: -100 | H11: FALSE | J11: =IF(H11=FALSE, A11, I11) -> 45301 | K11: =IF(G11=FALSE, E11-F11, 0) -> -100
A12: 45302 | B12: 2188 | C12: Expense 11 | D12: Gas/Automotive | E12: 100 | H12: FALSE | J12: =IF(H12=FALSE, A12, I12) -> 45302 | K12: =IF(G12=FALSE, E12-F12, 0) -> 100
A13: 45303 | B13: 2188 | C13: Expense 12 | D13: Dining | E13: -100 | H13: FALSE | J13: =IF(H13=FALSE, A13, I13) -> 45303 | K13: =IF(G13=FALSE, E13-F13, 0) -> -100
A14: 45304 | B14: 2188 | C14: Expense 13 | D14: Payment/Credit | E14: 7475 | H14: FALSE | J14: =IF(H14=FALSE, A14, I14) -> 45304 | K14: =IF(G14=FALSE, E14-F14, 0) -> 7475
... A17: 45307 | B17: 2188 | C17: Expense 16 | D17: Dining | E17: -100 | H17: FALSE | J17: =IF(H17=FALSE, A17, I17) -> 45307 | K17: =IF(G17=FALSE, E17-F17, 0) -> -100
A18: 45308 | B18: 2188 | C18: Expense 17 | D18: Dining | E18: 100 | G18: TRUE | H18: FALSE | J18: =IF(H18=FALSE, A18, I18) -> 45308 | K18: =IF(G18=FALSE, E18-F18, 0) -> 0
A19: 45309 | B19: 2188 | C19: Expense 18 | D19: Dining | E19: -100 | H19: FALSE | J19: =IF(H19=FALSE, A19, I19) -> 45309 | K19: =IF(G19=FALSE, E19-F19, 0) -> -100
A20: 45310 | B20: 2188 | C20: Expense 19 | D20: Dining | E20: 100 | H20: FALSE | J20: =IF(H20=FALSE, A20, I20) -> 45310 | K20: =IF(G20=FALSE, E20-F20, 0) -> 100
A21: 45311 | B21: 2188 | C21: Expense 20 | D21: Dining | E21: -100 | H21: FALSE | J21: =IF(H21=FALSE, A21, I21) -> 45311 | K21: =IF(G21=FALSE, E21-F21, 0) -> -100
A22: 45312 | B22: 2188 | C22: Expense 21 | D22: Dining | E22: 100 | H22: FALSE | J22: =IF(H22=FALSE, A22, I22) -> 45312 | K22: =IF(G22=FALSE, E22-F22, 0) -> 100
A23: 45313 | B23: 2188 | C23: Expense 22 | D23: Dining | E23: -100 | H23: FALSE | J23: =IF(H23=FALSE, A23, I23) -> 45313 | K23: =IF(G23=FALSE, E23-F23, 0) -> -100
A24: 45314 | B24: 2188 | C24: Expense 23 | D24: Dining | E24: 100 | H24: FALSE | J24: =IF(H24=FALSE, A24, I24) -> 45314 | K24: =IF(G24=FALSE, E24-F24, 0) -> 100
A25: 45315 | B25: 2188 | C25: Expense 24 | D25: Dining | E25: -100 | H25: FALSE | J25: =IF(H25=FALSE, A25, I25) -> 45315 | K25: =IF(G25=FALSE, E25-F25, 0) -> -100
A26: 45316 | B26: 2188 | C26: Expense 25 | D26: Dining | E26: 100 | H26: FALSE | J26: =IF(H26=FALSE, A26, I26) -> 45316 | K26: =IF(G26=FALSE, E26-F26, 0) -> 100
A27: 45317 | B27: 2188 | C27: Expense 26 | D27: Dining | E27: -100 | H27: FALSE | J27: =IF(H27=FALSE, A27, I27) -> 45317 | K27: =IF(G27=FALSE, E27-F27, 0) -> -100
A28: 45318 | B28: 2188 | C28: Expense 27 | D28: Other Travel | E28: 100 | H28: FALSE | J28: =IF(H28=FALSE, A28, I28) -> 45318 | K28: =IF(G28=FALSE, E28-F28, 0) -> 100
A29: 45319 | B29: 2188 | C29: Expense 28 | D29: Dining | E29: -100 | H29: FALSE | J29: =IF(H29=FALSE, A29, I29) -> 45319 | K29: =IF(G29=FALSE, E29-F29, 0) -> -100
A30: 45320 | B30: 2188 | C30: Expense 29 | D30: Merchandise | E30: 100 | H30: FALSE | J30: =IF(H30=FALSE, A30, I30) -> 45320 | K30: =IF(G30=FALSE, E30-F30, 0) -> 100
... A48: 45338 | B48: 2188 | C48: Expense 16 | D48: Dining | E48: -100 | H48: FALSE | J48: =IF(H48=FALSE, A48, I48) -> 45338 | K48: =IF(G48=FALSE, E48-F48, 0) -> -100
A49: 45339 | B49: 2188 | C49: Expense 17 | D49: Dining | E49: 100 | G49: TRUE | H49: FALSE | J49: =IF(H49=FALSE, A49, I49) -> 45339 | K49: =IF(G49=FALSE, E49-F49, 0) -> 0
A50: 45340 | B50: 2188 | C50: Expense 18 | D50: Dining | E50: -100 | H50: FALSE | J50: =IF(H50=FALSE, A50, I50) -> 45340 | K50: =IF(G50=FALSE, E50-F50, 0) -> -100
A51: 45341 | B51: 2188 | C51: Expense 19 | D51: Dining | E51: 100 | H51: FALSE | J51: =IF(H51=FALSE, A51, I51) -> 45341 | K51: =IF(G51=FALSE, E51-F51, 0) -> 100
A52: 45342 | B52: 2188 | C52: Expense 20 | D52: Dining | E52: -100 | H52: FALSE | J52: =IF(H52=FALSE, A52, I52) -> 45342 | K52: =IF(G52=FALSE, E52-F52, 0) -> -100
A53: 45343 | B53: 2188 | C53: Expense 21 | D53: Dining | E53: 100 | H53: FALSE | J53: =IF(H53=FALSE, A53, I53) -> 45343 | K53: =IF(G53=FALSE, E53-F53, 0) -> 100
A54: 45344 | B54: 2188 | C54: Expense 22 | D54: Dining | E54: -100 | H54: FALSE | J54: =IF(H54=FALSE, A54, I54) -> 45344 | K54: =IF(G54=FALSE, E54-F54, 0) -> -100
A55: 45345 | B55: 2188 | C55: Expense 23 | D55: Dining | E55: 100 | H55: FALSE | J55: =IF(H55=FALSE, A55, I55) -> 45345 | K55: =IF(G55=FALSE, E55-F55, 0) -> 100
A56: 45346 | B56: 2188 | C56: Expense 24 | D56: Dining | E56: -100 | H56: FALSE | J56: =IF(H56=FALSE, A56, I56) -> 45346 | K56: =IF(G56=FALSE, E56-F56, 0) -> -100
A57: 45347 | B57: 2188 | C57: Expense 25 | D57: Dining | E57: 100 | H57: FALSE | J57: =IF(H57=FALSE, A57, I57) -> 45347 | K57: =IF(G57=FALSE, E57-F57, 0) -> 100
A58: 45348 | B58: 2188 | C58: Expense 26 | D58: Dining | E58: -100 | H58: FALSE | J58: =IF(H58=FALSE, A58, I58) -> 45348 | K58: =IF(G58=FALSE, E58-F58, 0) -> -100
A59: 45349 | B59: 2188 | C59: Expense 27 | D59: Other Travel | E59: 100 | H59: FALSE | J59: =IF(H59=FALSE, A59, I59) -> 45349 | K59: =IF(G59=FALSE, E59-F59, 0) -> 100
...

Sheet Calculations
A1: Dates | B1: Test Account 1 | C1: Test Account 1 | D1: Test Account 3 | E1: Month | H1: Month | I1: Test Account 1 | J1: Test Account 2 | K1: Test Account 3 | L1: Totals | Q1: -1 | R1: -1 | S1: 1
B2: Amt1 | C2: Amt1 | D2: Amt1 | I2: Amt1 - | J2: Amt1 - | K2: Amt1 + | M2: Items | P2: Tags | Q2: Test Account 1 | R2: Test Account 2 | S2: Test Account 3 | T2: Totals
A3: 45292 | B3: =(SUMIF('Test Account 1'!$K:$K,Calculations!$A3,'Test Account 1'!$L:$L)*-1) -> -111 | C3: =(SUMIF('Test Account 2'!$K:$K,Calculations!$A3,'Test Account 2'!$L:$L)*-1) -> -111 | D3: =SUMIF('Test Account 3'!$J:$J,Calculations!$A3,'Test Account 3'!$K:$K) -> 111 | E3: =MONTH(A3) -> 1 | H3: 1 | I3: =SUMIF($E:$E,$H3,$B:$B) -> -2966 | J3: =SUMIF($E:$E,$H3,$C:$C) -> -4298 | K3: =SUMIF(E:E,H3,D:D) -> 7608 | L3: =SUM(I3:K3) -> 344 | P3: Apples 1 | Q3: =SUMIF('Test Account 1'!$D:$D,Calculations!$P3,'Test Account 1'!$L:$L)*$Q$1 -> -444 | R3: =SUMIF('Test Account 2'!$D:$D,Calculations!$P3,'Test Account 2'!$L:$L)*$R$1 -> -444 | S3: =SUMIF('Test Account 3'!$C:$C,Calculations!$P3,'Test Account 3'!$K:$K)*$S$1 -> 444 | T3: =SUM(Q3:S3) -> -444
A4: =A3+1 -> 45293 | B4: =(SUMIF('Test Account 1'!$K:$K,Calculations!$A4,'Test Account 1'!$L:$L)*-1) -> -222 | C4: =(SUMIF('Test Account 2'!$K:$K,Calculations!$A4,'Test Account 2'!$L:$L)*-1) -> -222 | D4: =SUMIF('Test Account 3'!$J:$J,Calculations!$A4,'Test Account 3'!$K:$K) -> -222 | E4: =MONTH(A4) -> 1 | H4: =H3+1 -> 2 | I4: =SUMIF($E:$E,$H4,$B:$B) -> -2633 | J4: =SUMIF($E:$E,$H4,$C:$C) -> -3965 | K4: =SUMIF(E:E,H4,D:D) -> 3780 | L4: =SUM(I4:K4) -> -2818 | P4: Oranges 2 | Q4: =SUMIF('Test Account 1'!$D:$D,Calculations!$P4,'Test Account 1'!$L:$L)*$Q$1 -> -888 | R4: =SUMIF('Test Account 2'!$D:$D,Calculations!$P4,'Test Account 2'!$L:$L)*$R$1 -> -888 | S4: =SUMIF('Test Account 3'!$C:$C,Calculations!$P4,'Test Account 3'!$K:$K)*$S$1 -> -888 | T4: =SUM(Q4:S4) -> -2664
A5: =A4+1 -> 45294 | B5: =(SUMIF('Test Account 1'!$K:$K,Calculations!$A5,'Test Account 1'!$L:$L)*-1) -> -333 | C5: =(SUMIF('Test Account 2'!$K:$K,Calculations!$A5,'Test Account 2'!$L:$L)*-1) -> -333 | D5: =SUMIF('Test Account 3'!$J:$J,Calculations!$A5,'Test Account 3'!$K:$K) -> 333 | E5: =MONTH(A5) -> 1 | H5: =H4+1 -> 3 | I5: =SUMIF($E:$E,$H5,$B:$B) -> -3965 | J5: =SUMIF($E:$E,$H5,$C:$C) -> -3965 | K5: =SUMIF(E:E,H5,D:D) -> 2056 | L5: =SUM(I5:K5) -> -5874 | P5: Grapes 3 | Q5: =SUMIF('Test Account 1'!$D:$D,Calculations!$P5,'Test Account 1'!$L:$L)*$Q$1 -> -666 | R5: =SUMIF('Test Account 2'!$D:$D,Calculations!$P5,'Test Account 2'!$L:$L)*$R$1 -> -1332 | S5: =SUMIF('Test Account 3'!$C:$C,Calculations!$P5,'Test Account 3'!$K:$K)*$S$1 -> 1332 | T5: =SUM(Q5:S5) -> -666
A6: =A5+1 -> 45295 | B6: =(SUMIF('Test Account 1'!$K:$K,Calculations!$A6,'Test Account 1'!$L:$L)*-1) -> -444 | C6: =(SUMIF('Test Account 2'!$K:$K,Calculations!$A6,'Test Account 2'!$L:$L)*-1) -> -444 | D6: =SUMIF('Test Account 3'!$J:$J,Calculations!$A6,'Test Account 3'!$K:$K) -> -444 | E6: =MONTH(A6) -> 1 | H6: =H5+1 -> 4 | I6: =SUMIF($E:$E,$H6,$B:$B) -> -3632 | J6: =SUMIF($E:$E,$H6,$C:$C) -> -3632 | K6: =SUMIF(E:E,H6,D:D) -> 1807 | L6: =SUM(I6:K6) -> -5457 | P6: Berry 4 | Q6: =SUMIF('Test Account 1'!$D:$D,Calculations!$P6,'Test Account 1'!$L:$L)*$Q$1 -> -888 | R6: =SUMIF('Test Account 2'!$D:$D,Calculations!$P6,'Test Account 2'!$L:$L)*$R$1 -> -1776 | S6: =SUMIF('Test Account 3'!$C:$C,Calculations!$P6,'Test Account 3'!$K:$K)*$S$1 -> -1776 | T6: =SUM(Q6:S6) -> -4440
A7: =A6+1 -> 45296 | B7: =(SUMIF('Test Account 1'!$K:$K,Calculations!$A7,'Test Account 1'!$L:$L)*-1) -> -555 | C7: =(SUMIF('Test Account 2'!$K:$K,Calculations!$A7,'Test Account 2'!$L:$L)*-1) -> -555 | D7: =SUMIF('Test Account 3'!$J:$J,Calculations!$A7,'Test Account 3'!$K:$K) -> 555 | E7: =MONTH(A7) -> 1 | H7: =H6+1 -> 5 | I7: =SUMIF($E:$E,$H7,$B:$B) -> 0 | J7: =SUMIF($E:$E,$H7,$C:$C) -> 0 | K7: =SUMIF($E:$E,$H7,$D:$D) -> 0 | L7: =SUM(I7:K7) -> 0 | P7: Watermelon 5 | Q7: =SUMIF('Test Account 1'!$D:$D,Calculations!$P7,'Test Account 1'!$L:$L)*$Q$1 -> -1110 | R7: =SUMIF('Test Account 2'!$D:$D,Calculations!$P7,'Test Account 2'!$L:$L)*$R$1 -> -2220 | S7: =SUMIF('Test Account 3'!$C:$C,Calculations!$P7,'Test Account 3'!$K:$K)*$S$1 -> 2220 | T7: =SUM(Q7:S7) -> -1110
A8: =A7+1 -> 45297 | B8: =(SUMIF('Test Account 1'!$K:$K,Calculations!$A8,'Test Account 1'!$L:$L)*-1) -> -100 | C8: =(SUMIF('Test Account 2'!$K:$K,Calculations!$A8,'Test Account 2'!$L:$L)*-1) -> -100 | D8: =SUMIF('Test Account 3'!$J:$J,Calculations!$A8,'Test Account 3'!$K:$K) -> -100 | E8: =MONTH(A8) -> 1 | H8: =H7+1 -> 6 | I8: =SUMIF($E:$E,$H8,$B:$B) -> 0 | J8: =SUMIF($E:$E,$H8,$C:$C) -> 0 | K8: =SUMIF($E:$E,$H8,$D:$D) -> 0 | L8: =SUM(I8:K8) -> 0
A9: =A8+1 -> 45298 | B9: =(SUMIF('Test Account 1'!$K:$K,Calculations!$A9,'Test Account 1'!$L:$L)*-1) -> -100 | C9: =(SUMIF('Test Account 2'!$K:$K,Calculations!$A9,'Test Account 2'!$L:$L)*-1) -> -100 | D9: =SUMIF('Test Account 3'!$J:$J,Calculations!$A9,'Test Account 3'!$K:$K) -> 100 | E9: =MONTH(A9) -> 1 | H9: =H8+1 -> 7 | I9: =SUMIF($E:$E,$H9,$B:$B) -> 0 | J9: =SUMIF($E:$E,$H9,$C:$C) -> 0 | K9: =SUMIF($E:$E,$H9,$D:$D) -> 0 | L9: =SUM(I9:K9) -> 0
A10: =A9+1 -> 45299 | B10: =(SUMIF('Test Account 1'!$K:$K,Calculations!$A10,'Test Account 1'!$L:$L)*-1) -> -100 | C10: =(SUMIF('Test Account 2'!$K:$K,Calculations!$A10,'Test Account 2'!$L:$L)*-1) -> -100 | D10: =SUMIF('Test Account 3'!$J:$J,Calculations!$A10,'Test Account 3'!$K:$K) -> -100 | E10: =MONTH(A10) -> 1 | H10: =H9+1 -> 8 | I10: =SUMIF($E:$E,$H10,$B:$B) -> 0 | J10: =SUMIF($E:$E,$H10,$C:$C) -> 0 | K10: =SUMIF($E:$E,$H10,$D:$D) -> 0 | L10: =SUM(I10:K10) -> 0
A11: =A10+1 -> 45300 | B11: =(SUMIF('Test Account 1'!$K:$K,Calculations!$A11,'Test Account 1'!$L:$L)*-1) -> -100 | C11: =(SUMIF('Test Account 2'!$K:$K,Calculations!$A11,'Test Account 2'!$L:$L)*-1) -> -100 | D11: =SUMIF('Test Account 3'!$J:$J,Calculations!$A11,'Test Account 3'!$K:$K) -> 100 | E11: =MONTH(A11) -> 1 | H11: =H10+1 -> 9 | I11: =SUMIF($E:$E,$H11,$B:$B) -> 0 | J11: =SUMIF($E:$E,$H11,$C:$C) -> 0 | K11: =SUMIF($E:$E,$H11,$D:$D) -> 0 | L11: =SUM(I11:K11) -> 0
A12: =A11+1 -> 45301 | B12: =(SUMIF('Test Account 1'!$K:$K,Calculations!$A12,'Test Account 1'!$L:$L)*-1) -> -100 | C12: =(SUMIF('Test Account 2'!$K:$K,Calculations!$A12,'Test Account 2'!$L:$L)*-1) -> -100 | D12: =SUMIF('Test Account 3'!$J:$J,Calculations!$A12,'Test Account 3'!$K:$K) -> -100 | E12: =MONTH(A12) -> 1 | H12: =H11+1 -> 10 | I12: =SUMIF($E:$E,$H12,$B:$B) -> 0 | J12: =SUMIF($E:$E,$H12,$C:$C) -> 0 | K12: =SUMIF($E:$E,$H12,$D:$D) -> 0 | L12: =SUM(I12:K12) -> 0
A13: =A12+1 -> 45302 | B13: =(SUMIF('Test Account 1'!$K:$K,Calculations!$A13,'Test Account 1'!$L:$L)*-1) -> -100 | C13: =(SUMIF('Test Account 2'!$K:$K,Calculations!$A13,'Test Account 2'!$L:$L)*-1) -> -100 | D13: =SUMIF('Test Account 3'!$J:$J,Calculations!$A13,'Test Account 3'!$K:$K) -> 100 | E13: =MONTH(A13) -> 1 | H13: =H12+1 -> 11 | I13: =SUMIF($E:$E,$H13,$B:$B) -> 0 | J13: =SUMIF($E:$E,$H13,$C:$C) -> 0 | K13: =SUMIF($E:$E,$H13,$D:$D) -> 0 | L13: =SUM(I13:K13) -> 0
A14: =A13+1 -> 45303 | B14: =(SUMIF('Test Account 1'!$K:$K,Calculations!$A14,'Test Account 1'!$L:$L)*-1) -> -100 | C14: =(SUMIF('Test Account 2'!$K:$K,Calculations!$A14,'Test Account 2'!$L:$L)*-1) -> -100 | D14: =SUMIF('Test Account 3'!$J:$J,Calculations!$A14,'Test Account 3'!$K:$K) -> -100 | E14: =MONTH(A14) -> 1 | H14: =H13+1 -> 12 | I14: =SUMIF($E:$E,$H14,$B:$B) -> 0 | J14: =SUMIF($E:$E,$H14,$C:$C) -> 0 | K14: =SUMIF($E:$E,$H14,$D:$D) -> 0 | L14: =SUM(I14:K14) -> 0
A15: =A14+1 -> 45304 | B15: =(SUMIF('Test Account 1'!$K:$K,Calculations!$A15,'Test Account 1'!$L:$L)*-1) -> 100 | C15: =(SUMIF('Test Account 2'!$K:$K,Calculations!$A15,'Test Account 2'!$L:$L)*-1) -> 100 | D15: =SUMIF('Test Account 3'!$J:$J,Calculations!$A15,'Test Account 3'!$K:$K) -> 7475 | E15: =MONTH(A15) -> 1 | I15: =SUM(I3:I14) -> -13196 | J15: =SUM(J3:J14) -> -15860 | K15: =SUM(K3:K14) -> 15251 | L15: =SUM(I15:K15) -> -13805
A16: =A15+1 -> 45305 | B16: =(SUMIF('Test Account 1'!$K:$K,Calculations!$A16,'Test Account 1'!$L:$L)*-1) -> -100 | C16: =(SUMIF('Test Account 2'!$K:$K,Calculations!$A16,'Test Account 2'!$L:$L)*-1) -> -100 | D16: =SUMIF('Test Account 3'!$J:$J,Calculations!$A16,'Test Account 3'!$K:$K) -> -100 | E16: =MONTH(A16) -> 1
A17: =A16+1 -> 45306 | B17: =(SUMIF('Test Account 1'!$K:$K,Calculations!$A17,'Test Account 1'!$L:$L)*-1) -> -100 | C17: =(SUMIF('Test Account 2'!$K:$K,Calculations!$A17,'Test Account 2'!$L:$L)*-1) -> -100 | D17: =SUMIF('Test Account 3'!$J:$J,Calculations!$A17,'Test Account 3'!$K:$K) -> 100 | E17: =MONTH(A17) -> 1 | L17: =SUM(L3:L14) -> -13805
A18: =A17+1 -> 45307 | B18: =(SUMIF('Test Account 1'!$K:$K,Calculations!$A18,'Test Account 1'!$L:$L)*-1) -> -100 | C18: =(SUMIF('Test Account 2'!$K:$K,Calculations!$A18,'Test Account 2'!$L:$L)*-1) -> -100 | D18: =SUMIF('Test Account 3'!$J:$J,Calculations!$A18,'Test Account 3'!$K:$K) -> -100 | E18: =MONTH(A18) -> 1
A19: =A18+1 -> 45308 | B19: =(SUMIF('Test Account 1'!$K:$K,Calculations!$A19,'Test Account 1'!$L:$L)*-1) -> 0 | C19: =(SUMIF('Test Account 2'!$K:$K,Calculations!$A19,'Test Account 2'!$L:$L)*-1) -> 0 | D19: =SUMIF('Test Account 3'!$J:$J,Calculations!$A19,'Test Account 3'!$K:$K) -> 0 | E19: =MONTH(A19) -> 1
A20: =A19+1 -> 45309 | B20: =(SUMIF('Test Account 1'!$K:$K,Calculations!$A20,'Test Account 1'!$L:$L)*-1) -> -100 | C20: =(SUMIF('Test Account 2'!$K:$K,Calculations!$A20,'Test Account 2'!$L:$L)*-1) -> -100 | D20: =SUMIF('Test Account 3'!$J:$J,Calculations!$A20,'Test Account 3'!$K:$K) -> -100 | E20: =MONTH(A20) -> 1
A21: =A20+1 -> 45310 | B21: =(SUMIF('Test Account 1'!$K:$K,Calculations!$A21,'Test Account 1'!$L:$L)*-1) -> -100 | C21: =(SUMIF('Test Account 2'!$K:$K,Calculations!$A21,'Test Account 2'!$L:$L)*-1) -> -100 | D21: =SUMIF('Test Account 3'!$J:$J,Calculations!$A21,'Test Account 3'!$K:$K) -> 100 | E21: =MONTH(A21) -> 1 | N21: =SUM(L3:L4) -> -2474
A22: =A21+1 -> 45311 | B22: =(SUMIF('Test Account 1'!$K:$K,Calculations!$A22,'Test Account 1'!$L:$L)*-1) -> -100 | C22: =(SUMIF('Test Account 2'!$K:$K,Calculations!$A22,'Test Account 2'!$L:$L)*-1) -> -100 | D22: =SUMIF('Test Account 3'!$J:$J,Calculations!$A22,'Test Account 3'!$K:$K) -> -100 | E22: =MONTH(A22) -> 1
A23: =A22+1 -> 45312 | B23: =(SUMIF('Test Account 1'!$K:$K,Calculations!$A23,'Test Account 1'!$L:$L)*-1) -> -100 | C23: =(SUMIF('Test Account 2'!$K:$K,Calculations!$A23,'Test Account 2'!$L:$L)*-1) -> -100 | D23: =SUMIF('Test Account 3'!$J:$J,Calculations!$A23,'Test Account 3'!$K:$K) -> 100 | E23: =MONTH(A23) -> 1
A24: =A23+1 -> 45313 | B24: =(SUMIF('Test Account 1'!$K:$K,Calculations!$A24,'Test Account 1'!$L:$L)*-1) -> -100 | C24: =(SUMIF('Test Account 2'!$K:$K,Calculations!$A24,'Test Account 2'!$L:$L)*-1) -> -100 | D24: =SUMIF('Test Account 3'!$J:$J,Calculations!$A24,'Test Account 3'!$K:$K) -> -100 | E24: =MONTH(A24) -> 1
A25: =A24+1 -> 45314 | B25: =(SUMIF('Test Account 1'!$K:$K,Calculations!$A25,'Test Account 1'!$L:$L)*-1) -> -100 | C25: =(SUMIF('Test Account 2'!$K:$K,Calculations!$A25,'Test Account 2'!$L:$L)*-1) -> -100 | D25: =SUMIF('Test Account 3'!$J:$J,Calculations!$A25,'Test Account 3'!$K:$K) -> 100 | E25: =MONTH(A25) -> 1
A26: =A25+1 -> 45315 | B26: =(SUMIF('Test Account 1'!$K:$K,Calculations!$A26,'Test Account 1'!$L:$L)*-1) -> -100 | C26: =(SUMIF('Test Account 2'!$K:$K,Calculations!$A26,'Test Account 2'!$L:$L)*-1) -> -100 | D26: =SUMIF('Test Account 3'!$J:$J,Calculations!$A26,'Test Account 3'!$K:$K) -> -100 | E26: =MONTH(A26) -> 1
A27: =A26+1 -> 45316 | B27: =(SUMIF('Test Account 1'!$K:$K,Calculations!$A27,'Test Account 1'!$L:$L)*-1) -> -100 | C27: =(SUMIF('Test Account 2'!$K:$K,Calculations!$A27,'Test Account 2'!$L:$L)*-1) -> -100 | D27: =SUMIF('Test Account 3'!$J:$J,Calculations!$A27,'Test Account 3'!$K:$K) -> 100 | E27: =MONTH(A27) -> 1
A28: =A27+1 -> 45317 | B28: =(SUMIF('Test Account 1'!$K:$K,Calculations!$A28,'Test Account 1'!$L:$L)*-1) -> -100 | C28: =(SUMIF('Test Account 2'!$K:$K,Calculations!$A28,'Test Account 2'!$L:$L)*-1) -> -100 | D28: =SUMIF('Test Account 3'!$J:$J,Calculations!$A28,'Test Account 3'!$K:$K) -> -100 | E28: =MONTH(A28) -> 1
A29: =A28+1 -> 45318 | B29: =(SUMIF('Test Account 1'!$K:$K,Calculations!$A29,'Test Account 1'!$L:$L)*-1) -> -100 | C29: =(SUMIF('Test Account 2'!$K:$K,Calculations!$A29,'Test Account 2'!$L:$L)*-1) -> -100 | D29: =SUMIF('Test Account 3'!$J:$J,Calculations!$A29,'Test Account 3'!$K:$K) -> 100 | E29: =MONTH(A29) -> 1
A30: =A29+1 -> 45319 | B30: =(SUMIF('Test Account 1'!$K:$K,Calculations!$A30,'Test Account 1'!$L:$L)*-1) -> -100 | C30: =(SUMIF('Test Account 2'!$K:$K,Calculations!$A30,'Test Account 2'!$L:$L)*-1) -> -100 | D30: =SUMIF('Test Account 3'!$J:$J,Calculations!$A30,'Test Account 3'!$K:$K) -> -100 | E30: =MONTH(A30) -> 1
A31: =A30+1 -> 45320 | B31: =(SUMIF('Test Account 1'!$K:$K,Calculations!$A31,'Test Account 1'!$L:$L)*-1) -> -100 | C31: =(SUMIF('Test Account 2'!$K:$K,Calculations!$A31,'Test Account 2'!$L:$L)*-1) -> -100 | D31: =SUMIF('Test Account 3'!$J:$J,Calculations!$A31,'Test Account 3'!$K:$K) -> 100 | E31: =MONTH(A31) -> 1
A32: =A31+1 -> 45321 | B32: =(SUMIF('Test Account 1'!$K:$K,Calculations!$A32,'Test Account 1'!$L:$L)*-1) -> -211 | C32: =(SUMIF('Test Account 2'!$K:$K,Calculations!$A32,'Test Account 2'!$L:$L)*-1) -> -211 | D32: =SUMIF('Test Account 3'!$J:$J,Calculations!$A32,'Test Account 3'!$K:$K) -> -100 | E32: =MONTH(A32) -> 1
A33: =A32+1 -> 45322 | B33: =(SUMIF('Test Account 1'!$K:$K,Calculations!$A33,'Test Account 1'!$L:$L)*-1) -> 1010 | C33: =(SUMIF('Test Account 2'!$K:$K,Calculations!$A33,'Test Account 2'!$L:$L)*-1) -> -322 | D33: =SUMIF('Test Account 3'!$J:$J,Calculations!$A33,'Test Account 3'!$K:$K) -> 100 | E33: =MONTH(A33) -> 1
A34: =A33+1 -> 45323 | B34: =(SUMIF('Test Account 1'!$K:$K,Calculations!$A34,'Test Account 1'!$L:$L)*-1) -> 0 | C34: =(SUMIF('Test Account 2'!$K:$K,Calculations!$A34,'Test Account 2'!$L:$L)*-1) -> -333 | D34: =SUMIF('Test Account 3'!$J:$J,Calculations!$A34,'Test Account 3'!$K:$K) -> 111 | E34: =MONTH(A34) -> 2 | F34: =SUM(B34:D34) -> -222 | G34: =F34 -> -222 | H34: =DAY(A34) -> 1
A35: =A34+1 -> 45324 | B35: =(SUMIF('Test Account 1'!$K:$K,Calculations!$A35,'Test Account 1'!$L:$L)*-1) -> 0 | C35: =(SUMIF('Test Account 2'!$K:$K,Calculations!$A35,'Test Account 2'!$L:$L)*-1) -> -444 | D35: =SUMIF('Test Account 3'!$J:$J,Calculations!$A35,'Test Account 3'!$K:$K) -> -222 | E35: =MONTH(A35) -> 2 | F35: =SUM(B35:D35) -> -666 | G35: =F35+G34 -> -888 | H35: =DAY(A35) -> 2
A36: =A35+1 -> 45325 | B36: =(SUMIF('Test Account 1'!$K:$K,Calculations!$A36,'Test Account 1'!$L:$L)*-1) -> 0 | C36: =(SUMIF('Test Account 2'!$K:$K,Calculations!$A36,'Test Account 2'!$L:$L)*-1) -> -555 | D36: =SUMIF('Test Account 3'!$J:$J,Calculations!$A36,'Test Account 3'!$K:$K) -> 333 | E36: =MONTH(A36) -> 2 | F36: =SUM(B36:D36) -> -222 | G36: =F36+G35 -> -1110 | H36: =DAY(A36) -> 3
A37: =A36+1 -> 45326 | B37: =(SUMIF('Test Account 1'!$K:$K,Calculations!$A37,'Test Account 1'!$L:$L)*-1) -> -100 | C37: =(SUMIF('Test Account 2'!$K:$K,Calculations!$A37,'Test Account 2'!$L:$L)*-1) -> -100 | D37: =SUMIF('Test Account 3'!$J:$J,Calculations!$A37,'Test Account 3'!$K:$K) -> -444 | E37: =MONTH(A37) -> 2 | F37: =SUM(B37:D37) -> -644 | G37: =F37+G36 -> -1754 | H37: =DAY(A37) -> 4
A38: =A37+1 -> 45327 | B38: =(SUMIF('Test Account 1'!$K:$K,Calculations!$A38,'Test Account 1'!$L:$L)*-1) -> -100 | C38: =(SUMIF('Test Account 2'!$K:$K,Calculations!$A38,'Test Account 2'!$L:$L)*-1) -> -100 | D38: =SUMIF('Test Account 3'!$J:$J,Calculations!$A38,'Test Account 3'!$K:$K) -> 555 | E38: =MONTH(A38) -> 2 | F38: =SUM(B38:D38) -> 355 | G38: =F38+G37 -> -1399 | H38: =DAY(A38) -> 5
A39: =A38+1 -> 45328 | B39: =(SUMIF('Test Account 1'!$K:$K,Calculations!$A39,'Test Account 1'!$L:$L)*-1) -> -100 | C39: =(SUMIF('Test Account 2'!$K:$K,Calculations!$A39,'Test Account 2'!$L:$L)*-1) -> -100 | D39: =SUMIF('Test Account 3'!$J:$J,Calculations!$A39,'Test Account 3'!$K:$K) -> -100 | E39: =MONTH(A39) -> 2 | F39: =SUM(B39:D39) -> -300 | G39: =F39+G38 -> -1699 | H39: =DAY(A39) -> 6
A40: =A39+1 -> 45329 | B40: =(SUMIF('Test Account 1'!$K:$K,Calculations!$A40,'Test Account 1'!$L:$L)*-1) -> -100 | C40: =(SUMIF('Test Account 2'!$K:$K,Calculations!$A40,'Test Account 2'!$L:$L)*-1) -> -100 | D40: =SUMIF('Test Account 3'!$J:$J,Calculations!$A40,'Test Account 3'!$K:$K) -> 100 | E40: =MONTH(A40) -> 2 | F40: =SUM(B40:D40) -> -100 | G40: =F40+G39 -> -1799 | H40: =DAY(A40) -> 7
...
